[2024-07-12T21:59:28.369+0000] {local_task_job_runner.py:120} INFO - ::group::Pre task execution logs
[2024-07-12T21:59:28.384+0000] {taskinstance.py:2076} INFO - Dependencies all met for dep_context=non-requeueable deps ti=<TaskInstance: upload_and_invoke_lambda.invoke_lambda_unzip manual__2024-07-12T21:54:18.440193+00:00 [queued]>
[2024-07-12T21:59:28.391+0000] {taskinstance.py:2076} INFO - Dependencies all met for dep_context=requeueable deps ti=<TaskInstance: upload_and_invoke_lambda.invoke_lambda_unzip manual__2024-07-12T21:54:18.440193+00:00 [queued]>
[2024-07-12T21:59:28.392+0000] {taskinstance.py:2306} INFO - Starting attempt 2 of 2
[2024-07-12T21:59:28.404+0000] {taskinstance.py:2330} INFO - Executing <Task(LambdaInvokeFunctionOperator): invoke_lambda_unzip> on 2024-07-12 21:54:18.440193+00:00
[2024-07-12T21:59:28.408+0000] {warnings.py:112} WARNING - /home/***/.local/lib/python3.12/site-packages/***/task/task_runner/standard_task_runner.py:61: DeprecationWarning: This process (pid=1817) is multi-threaded, use of fork() may lead to deadlocks in the child.
  pid = os.fork()

[2024-07-12T21:59:28.410+0000] {standard_task_runner.py:63} INFO - Started process 1818 to run task
[2024-07-12T21:59:28.410+0000] {standard_task_runner.py:90} INFO - Running: ['***', 'tasks', 'run', 'upload_and_invoke_lambda', 'invoke_lambda_unzip', 'manual__2024-07-12T21:54:18.440193+00:00', '--job-id', '222', '--raw', '--subdir', 'DAGS_FOLDER/stream_upload_to_s3.py', '--cfg-path', '/tmp/tmpkpw8r9wp']
[2024-07-12T21:59:28.411+0000] {standard_task_runner.py:91} INFO - Job 222: Subtask invoke_lambda_unzip
[2024-07-12T21:59:28.447+0000] {task_command.py:426} INFO - Running <TaskInstance: upload_and_invoke_lambda.invoke_lambda_unzip manual__2024-07-12T21:54:18.440193+00:00 [running]> on host e900ffca6a6f
[2024-07-12T21:59:28.534+0000] {taskinstance.py:2648} INFO - Exporting env vars: AIRFLOW_CTX_DAG_OWNER='***' AIRFLOW_CTX_DAG_ID='upload_and_invoke_lambda' AIRFLOW_CTX_TASK_ID='invoke_lambda_unzip' AIRFLOW_CTX_EXECUTION_DATE='2024-07-12T21:54:18.440193+00:00' AIRFLOW_CTX_TRY_NUMBER='2' AIRFLOW_CTX_DAG_RUN_ID='manual__2024-07-12T21:54:18.440193+00:00'
[2024-07-12T21:59:28.535+0000] {taskinstance.py:430} INFO - ::endgroup::
[2024-07-12T21:59:28.548+0000] {lambda_function.py:217} INFO - Invoking AWS Lambda function: ***-lamda-unzip with payload: {"s3_key": "ipl_matches.zip"}
[2024-07-12T21:59:28.556+0000] {base.py:84} INFO - Using connection ID 's3-bucket-conn' for task execution.
[2024-07-12T21:59:28.557+0000] {connection_wrapper.py:384} INFO - AWS Connection (conn_id='s3-bucket-conn', conn_type='aws') credentials retrieved from login and password.
[2024-07-12T21:59:29.236+0000] {lambda_function.py:226} INFO - Lambda response metadata: {'RequestId': '44122b57-c742-4578-9576-29350da10eff', 'HTTPStatusCode': 200, 'HTTPHeaders': {'date': 'Fri, 12 Jul 2024 21:59:30 GMT', 'content-type': 'application/json', 'content-length': '659', 'connection': 'keep-alive', 'x-amzn-requestid': '44122b57-c742-4578-9576-29350da10eff', 'x-amz-function-error': 'Unhandled', 'x-amzn-remapped-content-length': '0', 'x-amz-executed-version': '$LATEST', 'x-amzn-trace-id': 'root=1-6691a742-296c9b471639719922922cb3;parent=5c893a2bf025716e;sampled=0;lineage=101f7269:0'}, 'RetryAttempts': 0}
[2024-07-12T21:59:29.236+0000] {taskinstance.py:441} INFO - ::group::Post task execution logs
[2024-07-12T21:59:29.237+0000] {taskinstance.py:2905} ERROR - Task failed with exception
Traceback (most recent call last):
  File "/home/airflow/.local/lib/python3.12/site-packages/airflow/models/taskinstance.py", line 465, in _execute_task
    result = _execute_callable(context=context, **execute_callable_kwargs)
             ^^^^^^^^^^^^^^^^^^^^^^^^^^^^^^^^^^^^^^^^^^^^^^^^^^^^^^^^^^^^^
  File "/home/airflow/.local/lib/python3.12/site-packages/airflow/models/taskinstance.py", line 432, in _execute_callable
    return execute_callable(context=context, **execute_callable_kwargs)
           ^^^^^^^^^^^^^^^^^^^^^^^^^^^^^^^^^^^^^^^^^^^^^^^^^^^^^^^^^^^^
  File "/home/airflow/.local/lib/python3.12/site-packages/airflow/models/baseoperator.py", line 401, in wrapper
    return func(self, *args, **kwargs)
           ^^^^^^^^^^^^^^^^^^^^^^^^^^^
  File "/home/airflow/.local/lib/python3.12/site-packages/airflow/providers/amazon/aws/operators/lambda_function.py", line 246, in execute
    raise ValueError(
ValueError: ('Lambda function execution resulted in error', {'ResponseMetadata': {'RequestId': '44122b57-c742-4578-9576-29350da10eff', 'HTTPStatusCode': 200, 'HTTPHeaders': {'date': 'Fri, 12 Jul 2024 21:59:30 GMT', 'content-type': 'application/json', 'content-length': '659', 'connection': 'keep-alive', 'x-amzn-requestid': '44122b57-c742-4578-9576-29350da10eff', 'x-amz-function-error': 'Unhandled', 'x-amzn-remapped-content-length': '0', 'x-amz-executed-version': '$LATEST', 'x-amzn-trace-id': 'root=1-6691a742-296c9b471639719922922cb3;parent=5c893a2bf025716e;sampled=0;lineage=101f7269:0'}, 'RetryAttempts': 0}, 'Payload': '{"errorMessage": "An error occurred (AccessDenied) when calling the GetObject operation: Access Denied", "errorType": "ClientError", "requestId": "44122b57-c742-4578-9576-29350da10eff", "stackTrace": ["  File \\"/var/task/lambda_function.py\\", line 15, in lambda_handler\\n    zip_obj = s3_client.get_object(Bucket=source_bucket, Key=zip_key)\\n", "  File \\"/var/lang/lib/python3.11/site-packages/botocore/client.py\\", line 553, in _api_call\\n    return self._make_api_call(operation_name, kwargs)\\n", "  File \\"/var/lang/lib/python3.11/site-packages/botocore/client.py\\", line 1009, in _make_api_call\\n    raise error_class(parsed_response, operation_name)\\n"]}'})
[2024-07-12T21:59:29.245+0000] {taskinstance.py:1206} INFO - Marking task as FAILED. dag_id=upload_and_invoke_lambda, task_id=invoke_lambda_unzip, run_id=manual__2024-07-12T21:54:18.440193+00:00, execution_date=20240712T215418, start_date=20240712T215928, end_date=20240712T215929
[2024-07-12T21:59:29.267+0000] {standard_task_runner.py:110} ERROR - Failed to execute job 222 for task invoke_lambda_unzip (('Lambda function execution resulted in error', {'ResponseMetadata': {'RequestId': '44122b57-c742-4578-9576-29350da10eff', 'HTTPStatusCode': 200, 'HTTPHeaders': {'date': 'Fri, 12 Jul 2024 21:59:30 GMT', 'content-type': 'application/json', 'content-length': '659', 'connection': 'keep-alive', 'x-amzn-requestid': '44122b57-c742-4578-9576-29350da10eff', 'x-amz-function-error': 'Unhandled', 'x-amzn-remapped-content-length': '0', 'x-amz-executed-version': '$LATEST', 'x-amzn-trace-id': 'root=1-6691a742-296c9b471639719922922cb3;parent=5c893a2bf025716e;sampled=0;lineage=101f7269:0'}, 'RetryAttempts': 0}, 'Payload': '{"errorMessage": "An error occurred (AccessDenied) when calling the GetObject operation: Access Denied", "errorType": "ClientError", "requestId": "44122b57-c742-4578-9576-29350da10eff", "stackTrace": ["  File \\"/var/task/lambda_function.py\\", line 15, in lambda_handler\\n    zip_obj = s3_client.get_object(Bucket=source_bucket, Key=zip_key)\\n", "  File \\"/var/lang/lib/python3.11/site-packages/botocore/client.py\\", line 553, in _api_call\\n    return self._make_api_call(operation_name, kwargs)\\n", "  File \\"/var/lang/lib/python3.11/site-packages/botocore/client.py\\", line 1009, in _make_api_call\\n    raise error_class(parsed_response, operation_name)\\n"]}'}); 1818)
[2024-07-12T21:59:29.306+0000] {local_task_job_runner.py:240} INFO - Task exited with return code 1
[2024-07-12T21:59:29.318+0000] {taskinstance.py:3503} INFO - 0 downstream tasks scheduled from follow-on schedule check
[2024-07-12T21:59:29.321+0000] {local_task_job_runner.py:222} INFO - ::endgroup::
