[2024-07-16T04:37:48.418+0000] {local_task_job_runner.py:120} INFO - ::group::Pre task execution logs
[2024-07-16T04:37:48.442+0000] {taskinstance.py:2076} INFO - Dependencies all met for dep_context=non-requeueable deps ti=<TaskInstance: glue_crawler_etl_pipeline.start_glue_crawler manual__2024-07-16T04:37:47.167332+00:00 [queued]>
[2024-07-16T04:37:48.457+0000] {taskinstance.py:2076} INFO - Dependencies all met for dep_context=requeueable deps ti=<TaskInstance: glue_crawler_etl_pipeline.start_glue_crawler manual__2024-07-16T04:37:47.167332+00:00 [queued]>
[2024-07-16T04:37:48.457+0000] {taskinstance.py:2306} INFO - Starting attempt 1 of 2
[2024-07-16T04:37:48.476+0000] {taskinstance.py:2330} INFO - Executing <Task(GlueCrawlerOperator): start_glue_crawler> on 2024-07-16 04:37:47.167332+00:00
[2024-07-16T04:37:48.484+0000] {warnings.py:112} WARNING - /home/***/.local/lib/python3.12/site-packages/***/task/task_runner/standard_task_runner.py:61: DeprecationWarning: This process (pid=386) is multi-threaded, use of fork() may lead to deadlocks in the child.
  pid = os.fork()

[2024-07-16T04:37:48.486+0000] {standard_task_runner.py:63} INFO - Started process 387 to run task
[2024-07-16T04:37:48.486+0000] {standard_task_runner.py:90} INFO - Running: ['***', 'tasks', 'run', 'glue_crawler_etl_pipeline', 'start_glue_crawler', 'manual__2024-07-16T04:37:47.167332+00:00', '--job-id', '264', '--raw', '--subdir', 'DAGS_FOLDER/etl_populate_database.py', '--cfg-path', '/tmp/tmp87572eu2']
[2024-07-16T04:37:48.487+0000] {standard_task_runner.py:91} INFO - Job 264: Subtask start_glue_crawler
[2024-07-16T04:37:48.541+0000] {task_command.py:426} INFO - Running <TaskInstance: glue_crawler_etl_pipeline.start_glue_crawler manual__2024-07-16T04:37:47.167332+00:00 [running]> on host 0ec6e6e2bd09
[2024-07-16T04:37:48.643+0000] {taskinstance.py:2648} INFO - Exporting env vars: AIRFLOW_CTX_DAG_EMAIL='your_email@example.com' AIRFLOW_CTX_DAG_OWNER='***' AIRFLOW_CTX_DAG_ID='glue_crawler_etl_pipeline' AIRFLOW_CTX_TASK_ID='start_glue_crawler' AIRFLOW_CTX_EXECUTION_DATE='2024-07-16T04:37:47.167332+00:00' AIRFLOW_CTX_TRY_NUMBER='1' AIRFLOW_CTX_DAG_RUN_ID='manual__2024-07-16T04:37:47.167332+00:00'
[2024-07-16T04:37:48.644+0000] {taskinstance.py:430} INFO - ::endgroup::
[2024-07-16T04:37:48.662+0000] {glue_crawler.py:57} INFO - Checking if crawler already exists: IplJsonCrawler
[2024-07-16T04:37:48.674+0000] {base.py:84} INFO - Using connection ID 's3-bucket-conn' for task execution.
[2024-07-16T04:37:48.675+0000] {connection_wrapper.py:384} INFO - AWS Connection (conn_id='s3-bucket-conn', conn_type='aws') credentials retrieved from login and password.
[2024-07-16T04:37:49.740+0000] {glue_crawler.py:100} INFO - Updating crawler: IplJsonCrawler
[2024-07-16T04:37:50.033+0000] {taskinstance.py:441} INFO - ::group::Post task execution logs
[2024-07-16T04:37:50.034+0000] {taskinstance.py:2905} ERROR - Task failed with exception
Traceback (most recent call last):
  File "/home/airflow/.local/lib/python3.12/site-packages/airflow/models/taskinstance.py", line 465, in _execute_task
    result = _execute_callable(context=context, **execute_callable_kwargs)
             ^^^^^^^^^^^^^^^^^^^^^^^^^^^^^^^^^^^^^^^^^^^^^^^^^^^^^^^^^^^^^
  File "/home/airflow/.local/lib/python3.12/site-packages/airflow/models/taskinstance.py", line 432, in _execute_callable
    return execute_callable(context=context, **execute_callable_kwargs)
           ^^^^^^^^^^^^^^^^^^^^^^^^^^^^^^^^^^^^^^^^^^^^^^^^^^^^^^^^^^^^
  File "/home/airflow/.local/lib/python3.12/site-packages/airflow/models/baseoperator.py", line 401, in wrapper
    return func(self, *args, **kwargs)
           ^^^^^^^^^^^^^^^^^^^^^^^^^^^
  File "/home/airflow/.local/lib/python3.12/site-packages/airflow/providers/amazon/aws/operators/glue_crawler.py", line 94, in execute
    self.hook.update_crawler(**self.config)
  File "/home/airflow/.local/lib/python3.12/site-packages/airflow/providers/amazon/aws/hooks/glue_crawler.py", line 101, in update_crawler
    self.glue_client.update_crawler(**crawler_kwargs)
  File "/home/airflow/.local/lib/python3.12/site-packages/botocore/client.py", line 565, in _api_call
    return self._make_api_call(operation_name, kwargs)
           ^^^^^^^^^^^^^^^^^^^^^^^^^^^^^^^^^^^^^^^^^^^
  File "/home/airflow/.local/lib/python3.12/site-packages/botocore/client.py", line 1021, in _make_api_call
    raise error_class(parsed_response, operation_name)
botocore.errorfactory.InvalidInputException: An error occurred (InvalidInputException) when calling the UpdateCrawler operation: Service is unable to assume provided role. Please verify role's TrustPolicy
[2024-07-16T04:37:50.044+0000] {taskinstance.py:1206} INFO - Marking task as UP_FOR_RETRY. dag_id=glue_crawler_etl_pipeline, task_id=start_glue_crawler, run_id=manual__2024-07-16T04:37:47.167332+00:00, execution_date=20240716T043747, start_date=20240716T043748, end_date=20240716T043750
[2024-07-16T04:37:50.060+0000] {standard_task_runner.py:110} ERROR - Failed to execute job 264 for task start_glue_crawler (An error occurred (InvalidInputException) when calling the UpdateCrawler operation: Service is unable to assume provided role. Please verify role's TrustPolicy; 387)
[2024-07-16T04:37:50.106+0000] {local_task_job_runner.py:240} INFO - Task exited with return code 1
[2024-07-16T04:37:50.135+0000] {taskinstance.py:3503} INFO - 0 downstream tasks scheduled from follow-on schedule check
[2024-07-16T04:37:50.137+0000] {local_task_job_runner.py:222} INFO - ::endgroup::
