[2024-07-12T21:57:20.881+0000] {local_task_job_runner.py:120} INFO - ::group::Pre task execution logs
[2024-07-12T21:57:20.896+0000] {taskinstance.py:2076} INFO - Dependencies all met for dep_context=non-requeueable deps ti=<TaskInstance: upload_and_invoke_lambda.invoke_lambda_unzip manual__2024-07-12T21:57:14.202898+00:00 [queued]>
[2024-07-12T21:57:20.904+0000] {taskinstance.py:2076} INFO - Dependencies all met for dep_context=requeueable deps ti=<TaskInstance: upload_and_invoke_lambda.invoke_lambda_unzip manual__2024-07-12T21:57:14.202898+00:00 [queued]>
[2024-07-12T21:57:20.905+0000] {taskinstance.py:2306} INFO - Starting attempt 1 of 2
[2024-07-12T21:57:20.919+0000] {taskinstance.py:2330} INFO - Executing <Task(LambdaInvokeFunctionOperator): invoke_lambda_unzip> on 2024-07-12 21:57:14.202898+00:00
[2024-07-12T21:57:20.924+0000] {warnings.py:112} WARNING - /home/***/.local/lib/python3.12/site-packages/***/task/task_runner/standard_task_runner.py:61: DeprecationWarning: This process (pid=1786) is multi-threaded, use of fork() may lead to deadlocks in the child.
  pid = os.fork()

[2024-07-12T21:57:20.925+0000] {standard_task_runner.py:63} INFO - Started process 1787 to run task
[2024-07-12T21:57:20.925+0000] {standard_task_runner.py:90} INFO - Running: ['***', 'tasks', 'run', 'upload_and_invoke_lambda', 'invoke_lambda_unzip', 'manual__2024-07-12T21:57:14.202898+00:00', '--job-id', '221', '--raw', '--subdir', 'DAGS_FOLDER/stream_upload_to_s3.py', '--cfg-path', '/tmp/tmpu7njcaoc']
[2024-07-12T21:57:20.926+0000] {standard_task_runner.py:91} INFO - Job 221: Subtask invoke_lambda_unzip
[2024-07-12T21:57:20.965+0000] {task_command.py:426} INFO - Running <TaskInstance: upload_and_invoke_lambda.invoke_lambda_unzip manual__2024-07-12T21:57:14.202898+00:00 [running]> on host e900ffca6a6f
[2024-07-12T21:57:21.051+0000] {taskinstance.py:2648} INFO - Exporting env vars: AIRFLOW_CTX_DAG_OWNER='***' AIRFLOW_CTX_DAG_ID='upload_and_invoke_lambda' AIRFLOW_CTX_TASK_ID='invoke_lambda_unzip' AIRFLOW_CTX_EXECUTION_DATE='2024-07-12T21:57:14.202898+00:00' AIRFLOW_CTX_TRY_NUMBER='1' AIRFLOW_CTX_DAG_RUN_ID='manual__2024-07-12T21:57:14.202898+00:00'
[2024-07-12T21:57:21.052+0000] {taskinstance.py:430} INFO - ::endgroup::
[2024-07-12T21:57:21.064+0000] {lambda_function.py:217} INFO - Invoking AWS Lambda function: ***-lamda-unzip with payload: {"s3_key": "ipl_matches.zip"}
[2024-07-12T21:57:21.075+0000] {base.py:84} INFO - Using connection ID 's3-bucket-conn' for task execution.
[2024-07-12T21:57:21.075+0000] {connection_wrapper.py:384} INFO - AWS Connection (conn_id='s3-bucket-conn', conn_type='aws') credentials retrieved from login and password.
[2024-07-12T21:57:22.430+0000] {lambda_function.py:226} INFO - Lambda response metadata: {'RequestId': '844d301d-852d-4f0e-ac48-765e9f6098b4', 'HTTPStatusCode': 200, 'HTTPHeaders': {'date': 'Fri, 12 Jul 2024 21:57:23 GMT', 'content-type': 'application/json', 'content-length': '659', 'connection': 'keep-alive', 'x-amzn-requestid': '844d301d-852d-4f0e-ac48-765e9f6098b4', 'x-amz-function-error': 'Unhandled', 'x-amzn-remapped-content-length': '0', 'x-amz-executed-version': '$LATEST', 'x-amzn-trace-id': 'root=1-6691a6c2-756af452403937b0307d5433;parent=38e46737adde0291;sampled=0;lineage=101f7269:0'}, 'RetryAttempts': 0}
[2024-07-12T21:57:22.432+0000] {taskinstance.py:441} INFO - ::group::Post task execution logs
[2024-07-12T21:57:22.432+0000] {taskinstance.py:2905} ERROR - Task failed with exception
Traceback (most recent call last):
  File "/home/airflow/.local/lib/python3.12/site-packages/airflow/models/taskinstance.py", line 465, in _execute_task
    result = _execute_callable(context=context, **execute_callable_kwargs)
             ^^^^^^^^^^^^^^^^^^^^^^^^^^^^^^^^^^^^^^^^^^^^^^^^^^^^^^^^^^^^^
  File "/home/airflow/.local/lib/python3.12/site-packages/airflow/models/taskinstance.py", line 432, in _execute_callable
    return execute_callable(context=context, **execute_callable_kwargs)
           ^^^^^^^^^^^^^^^^^^^^^^^^^^^^^^^^^^^^^^^^^^^^^^^^^^^^^^^^^^^^
  File "/home/airflow/.local/lib/python3.12/site-packages/airflow/models/baseoperator.py", line 401, in wrapper
    return func(self, *args, **kwargs)
           ^^^^^^^^^^^^^^^^^^^^^^^^^^^
  File "/home/airflow/.local/lib/python3.12/site-packages/airflow/providers/amazon/aws/operators/lambda_function.py", line 246, in execute
    raise ValueError(
ValueError: ('Lambda function execution resulted in error', {'ResponseMetadata': {'RequestId': '844d301d-852d-4f0e-ac48-765e9f6098b4', 'HTTPStatusCode': 200, 'HTTPHeaders': {'date': 'Fri, 12 Jul 2024 21:57:23 GMT', 'content-type': 'application/json', 'content-length': '659', 'connection': 'keep-alive', 'x-amzn-requestid': '844d301d-852d-4f0e-ac48-765e9f6098b4', 'x-amz-function-error': 'Unhandled', 'x-amzn-remapped-content-length': '0', 'x-amz-executed-version': '$LATEST', 'x-amzn-trace-id': 'root=1-6691a6c2-756af452403937b0307d5433;parent=38e46737adde0291;sampled=0;lineage=101f7269:0'}, 'RetryAttempts': 0}, 'Payload': '{"errorMessage": "An error occurred (AccessDenied) when calling the GetObject operation: Access Denied", "errorType": "ClientError", "requestId": "844d301d-852d-4f0e-ac48-765e9f6098b4", "stackTrace": ["  File \\"/var/task/lambda_function.py\\", line 15, in lambda_handler\\n    zip_obj = s3_client.get_object(Bucket=source_bucket, Key=zip_key)\\n", "  File \\"/var/lang/lib/python3.11/site-packages/botocore/client.py\\", line 553, in _api_call\\n    return self._make_api_call(operation_name, kwargs)\\n", "  File \\"/var/lang/lib/python3.11/site-packages/botocore/client.py\\", line 1009, in _make_api_call\\n    raise error_class(parsed_response, operation_name)\\n"]}'})
[2024-07-12T21:57:22.442+0000] {taskinstance.py:1206} INFO - Marking task as UP_FOR_RETRY. dag_id=upload_and_invoke_lambda, task_id=invoke_lambda_unzip, run_id=manual__2024-07-12T21:57:14.202898+00:00, execution_date=20240712T215714, start_date=20240712T215720, end_date=20240712T215722
[2024-07-12T21:57:22.456+0000] {standard_task_runner.py:110} ERROR - Failed to execute job 221 for task invoke_lambda_unzip (('Lambda function execution resulted in error', {'ResponseMetadata': {'RequestId': '844d301d-852d-4f0e-ac48-765e9f6098b4', 'HTTPStatusCode': 200, 'HTTPHeaders': {'date': 'Fri, 12 Jul 2024 21:57:23 GMT', 'content-type': 'application/json', 'content-length': '659', 'connection': 'keep-alive', 'x-amzn-requestid': '844d301d-852d-4f0e-ac48-765e9f6098b4', 'x-amz-function-error': 'Unhandled', 'x-amzn-remapped-content-length': '0', 'x-amz-executed-version': '$LATEST', 'x-amzn-trace-id': 'root=1-6691a6c2-756af452403937b0307d5433;parent=38e46737adde0291;sampled=0;lineage=101f7269:0'}, 'RetryAttempts': 0}, 'Payload': '{"errorMessage": "An error occurred (AccessDenied) when calling the GetObject operation: Access Denied", "errorType": "ClientError", "requestId": "844d301d-852d-4f0e-ac48-765e9f6098b4", "stackTrace": ["  File \\"/var/task/lambda_function.py\\", line 15, in lambda_handler\\n    zip_obj = s3_client.get_object(Bucket=source_bucket, Key=zip_key)\\n", "  File \\"/var/lang/lib/python3.11/site-packages/botocore/client.py\\", line 553, in _api_call\\n    return self._make_api_call(operation_name, kwargs)\\n", "  File \\"/var/lang/lib/python3.11/site-packages/botocore/client.py\\", line 1009, in _make_api_call\\n    raise error_class(parsed_response, operation_name)\\n"]}'}); 1787)
[2024-07-12T21:57:22.465+0000] {local_task_job_runner.py:240} INFO - Task exited with return code 1
[2024-07-12T21:57:22.479+0000] {taskinstance.py:3503} INFO - 0 downstream tasks scheduled from follow-on schedule check
[2024-07-12T21:57:22.481+0000] {local_task_job_runner.py:222} INFO - ::endgroup::
