[2024-07-16T07:12:57.068+0000] {local_task_job_runner.py:120} INFO - ::group::Pre task execution logs
[2024-07-16T07:12:57.089+0000] {taskinstance.py:2076} INFO - Dependencies all met for dep_context=non-requeueable deps ti=<TaskInstance: glue_crawler_etl_pipeline.log_crawler_status manual__2024-07-16T07:09:02.837883+00:00 [queued]>
[2024-07-16T07:12:57.098+0000] {taskinstance.py:2076} INFO - Dependencies all met for dep_context=requeueable deps ti=<TaskInstance: glue_crawler_etl_pipeline.log_crawler_status manual__2024-07-16T07:09:02.837883+00:00 [queued]>
[2024-07-16T07:12:57.099+0000] {taskinstance.py:2306} INFO - Starting attempt 1 of 2
[2024-07-16T07:12:57.112+0000] {taskinstance.py:2330} INFO - Executing <Task(PythonOperator): log_crawler_status> on 2024-07-16 07:09:02.837883+00:00
[2024-07-16T07:12:57.116+0000] {warnings.py:112} WARNING - /home/***/.local/lib/python3.12/site-packages/***/task/task_runner/standard_task_runner.py:61: DeprecationWarning: This process (pid=2378) is multi-threaded, use of fork() may lead to deadlocks in the child.
  pid = os.fork()

[2024-07-16T07:12:57.117+0000] {standard_task_runner.py:63} INFO - Started process 2379 to run task
[2024-07-16T07:12:57.118+0000] {standard_task_runner.py:90} INFO - Running: ['***', 'tasks', 'run', 'glue_crawler_etl_pipeline', 'log_crawler_status', 'manual__2024-07-16T07:09:02.837883+00:00', '--job-id', '277', '--raw', '--subdir', 'DAGS_FOLDER/etl_populate_database.py', '--cfg-path', '/tmp/tmpjsiguavj']
[2024-07-16T07:12:57.119+0000] {standard_task_runner.py:91} INFO - Job 277: Subtask log_crawler_status
[2024-07-16T07:12:57.157+0000] {task_command.py:426} INFO - Running <TaskInstance: glue_crawler_etl_pipeline.log_crawler_status manual__2024-07-16T07:09:02.837883+00:00 [running]> on host 0ec6e6e2bd09
[2024-07-16T07:12:57.228+0000] {taskinstance.py:2648} INFO - Exporting env vars: AIRFLOW_CTX_DAG_EMAIL='your_email@example.com' AIRFLOW_CTX_DAG_OWNER='***' AIRFLOW_CTX_DAG_ID='glue_crawler_etl_pipeline' AIRFLOW_CTX_TASK_ID='log_crawler_status' AIRFLOW_CTX_EXECUTION_DATE='2024-07-16T07:09:02.837883+00:00' AIRFLOW_CTX_TRY_NUMBER='1' AIRFLOW_CTX_DAG_RUN_ID='manual__2024-07-16T07:09:02.837883+00:00'
[2024-07-16T07:12:57.229+0000] {taskinstance.py:430} INFO - ::endgroup::
[2024-07-16T07:12:57.336+0000] {taskinstance.py:441} INFO - ::group::Post task execution logs
[2024-07-16T07:12:57.336+0000] {taskinstance.py:2905} ERROR - Task failed with exception
Traceback (most recent call last):
  File "/home/airflow/.local/lib/python3.12/site-packages/airflow/models/taskinstance.py", line 465, in _execute_task
    result = _execute_callable(context=context, **execute_callable_kwargs)
             ^^^^^^^^^^^^^^^^^^^^^^^^^^^^^^^^^^^^^^^^^^^^^^^^^^^^^^^^^^^^^
  File "/home/airflow/.local/lib/python3.12/site-packages/airflow/models/taskinstance.py", line 432, in _execute_callable
    return execute_callable(context=context, **execute_callable_kwargs)
           ^^^^^^^^^^^^^^^^^^^^^^^^^^^^^^^^^^^^^^^^^^^^^^^^^^^^^^^^^^^^
  File "/home/airflow/.local/lib/python3.12/site-packages/airflow/models/baseoperator.py", line 401, in wrapper
    return func(self, *args, **kwargs)
           ^^^^^^^^^^^^^^^^^^^^^^^^^^^
  File "/home/airflow/.local/lib/python3.12/site-packages/airflow/operators/python.py", line 235, in execute
    return_value = self.execute_callable()
                   ^^^^^^^^^^^^^^^^^^^^^^^
  File "/home/airflow/.local/lib/python3.12/site-packages/airflow/operators/python.py", line 252, in execute_callable
    return self.python_callable(*self.op_args, **self.op_kwargs)
           ^^^^^^^^^^^^^^^^^^^^^^^^^^^^^^^^^^^^^^^^^^^^^^^^^^^^^
  File "/opt/airflow/dags/etl_populate_database.py", line 81, in log_crawler_status
    response = client.get_crawler(Name='IplJsonCrawler')
               ^^^^^^^^^^^^^^^^^^^^^^^^^^^^^^^^^^^^^^^^^
  File "/home/airflow/.local/lib/python3.12/site-packages/botocore/client.py", line 565, in _api_call
    return self._make_api_call(operation_name, kwargs)
           ^^^^^^^^^^^^^^^^^^^^^^^^^^^^^^^^^^^^^^^^^^^
  File "/home/airflow/.local/lib/python3.12/site-packages/botocore/client.py", line 1001, in _make_api_call
    http, parsed_response = self._make_request(
                            ^^^^^^^^^^^^^^^^^^^
  File "/home/airflow/.local/lib/python3.12/site-packages/botocore/client.py", line 1027, in _make_request
    return self._endpoint.make_request(operation_model, request_dict)
           ^^^^^^^^^^^^^^^^^^^^^^^^^^^^^^^^^^^^^^^^^^^^^^^^^^^^^^^^^^
  File "/home/airflow/.local/lib/python3.12/site-packages/botocore/endpoint.py", line 119, in make_request
    return self._send_request(request_dict, operation_model)
           ^^^^^^^^^^^^^^^^^^^^^^^^^^^^^^^^^^^^^^^^^^^^^^^^^
  File "/home/airflow/.local/lib/python3.12/site-packages/botocore/endpoint.py", line 198, in _send_request
    request = self.create_request(request_dict, operation_model)
              ^^^^^^^^^^^^^^^^^^^^^^^^^^^^^^^^^^^^^^^^^^^^^^^^^^
  File "/home/airflow/.local/lib/python3.12/site-packages/botocore/endpoint.py", line 134, in create_request
    self._event_emitter.emit(
  File "/home/airflow/.local/lib/python3.12/site-packages/botocore/hooks.py", line 412, in emit
    return self._emitter.emit(aliased_event_name, **kwargs)
           ^^^^^^^^^^^^^^^^^^^^^^^^^^^^^^^^^^^^^^^^^^^^^^^^
  File "/home/airflow/.local/lib/python3.12/site-packages/botocore/hooks.py", line 256, in emit
    return self._emit(event_name, kwargs)
           ^^^^^^^^^^^^^^^^^^^^^^^^^^^^^^
  File "/home/airflow/.local/lib/python3.12/site-packages/botocore/hooks.py", line 239, in _emit
    response = handler(**kwargs)
               ^^^^^^^^^^^^^^^^^
  File "/home/airflow/.local/lib/python3.12/site-packages/botocore/signers.py", line 105, in handler
    return self.sign(operation_name, request)
           ^^^^^^^^^^^^^^^^^^^^^^^^^^^^^^^^^^
  File "/home/airflow/.local/lib/python3.12/site-packages/botocore/signers.py", line 199, in sign
    auth.add_auth(request)
  File "/home/airflow/.local/lib/python3.12/site-packages/botocore/auth.py", line 418, in add_auth
    raise NoCredentialsError()
botocore.exceptions.NoCredentialsError: Unable to locate credentials
[2024-07-16T07:12:57.348+0000] {taskinstance.py:1206} INFO - Marking task as UP_FOR_RETRY. dag_id=glue_crawler_etl_pipeline, task_id=log_crawler_status, run_id=manual__2024-07-16T07:09:02.837883+00:00, execution_date=20240716T070902, start_date=20240716T071257, end_date=20240716T071257
[2024-07-16T07:12:57.359+0000] {standard_task_runner.py:110} ERROR - Failed to execute job 277 for task log_crawler_status (Unable to locate credentials; 2379)
[2024-07-16T07:12:57.372+0000] {local_task_job_runner.py:240} INFO - Task exited with return code 1
[2024-07-16T07:12:57.391+0000] {taskinstance.py:3503} INFO - 0 downstream tasks scheduled from follow-on schedule check
[2024-07-16T07:12:57.393+0000] {local_task_job_runner.py:222} INFO - ::endgroup::
