[2024-07-16T07:53:26.186+0000] {local_task_job_runner.py:120} INFO - ::group::Pre task execution logs
[2024-07-16T07:53:26.205+0000] {taskinstance.py:2076} INFO - Dependencies all met for dep_context=non-requeueable deps ti=<TaskInstance: glue_crawler_etl_pipeline.start_glue_job manual__2024-07-16T07:49:57.063900+00:00 [queued]>
[2024-07-16T07:53:26.213+0000] {taskinstance.py:2076} INFO - Dependencies all met for dep_context=requeueable deps ti=<TaskInstance: glue_crawler_etl_pipeline.start_glue_job manual__2024-07-16T07:49:57.063900+00:00 [queued]>
[2024-07-16T07:53:26.214+0000] {taskinstance.py:2306} INFO - Starting attempt 1 of 2
[2024-07-16T07:53:26.226+0000] {taskinstance.py:2330} INFO - Executing <Task(PythonOperator): start_glue_job> on 2024-07-16 07:49:57.063900+00:00
[2024-07-16T07:53:26.231+0000] {warnings.py:112} WARNING - /home/***/.local/lib/python3.12/site-packages/***/task/task_runner/standard_task_runner.py:61: DeprecationWarning: This process (pid=2942) is multi-threaded, use of fork() may lead to deadlocks in the child.
  pid = os.fork()

[2024-07-16T07:53:26.233+0000] {standard_task_runner.py:63} INFO - Started process 2943 to run task
[2024-07-16T07:53:26.233+0000] {standard_task_runner.py:90} INFO - Running: ['***', 'tasks', 'run', 'glue_crawler_etl_pipeline', 'start_glue_job', 'manual__2024-07-16T07:49:57.063900+00:00', '--job-id', '299', '--raw', '--subdir', 'DAGS_FOLDER/etl_populate_database.py', '--cfg-path', '/tmp/tmpjzrssp3h']
[2024-07-16T07:53:26.234+0000] {standard_task_runner.py:91} INFO - Job 299: Subtask start_glue_job
[2024-07-16T07:53:26.275+0000] {task_command.py:426} INFO - Running <TaskInstance: glue_crawler_etl_pipeline.start_glue_job manual__2024-07-16T07:49:57.063900+00:00 [running]> on host 0ec6e6e2bd09
[2024-07-16T07:53:26.347+0000] {taskinstance.py:2648} INFO - Exporting env vars: AIRFLOW_CTX_DAG_EMAIL='your_email@example.com' AIRFLOW_CTX_DAG_OWNER='***' AIRFLOW_CTX_DAG_ID='glue_crawler_etl_pipeline' AIRFLOW_CTX_TASK_ID='start_glue_job' AIRFLOW_CTX_EXECUTION_DATE='2024-07-16T07:49:57.063900+00:00' AIRFLOW_CTX_TRY_NUMBER='1' AIRFLOW_CTX_DAG_RUN_ID='manual__2024-07-16T07:49:57.063900+00:00'
[2024-07-16T07:53:26.348+0000] {taskinstance.py:430} INFO - ::endgroup::
[2024-07-16T07:53:26.368+0000] {base.py:84} INFO - Using connection ID 's3-bucket-conn' for task execution.
[2024-07-16T07:53:26.772+0000] {etl_populate_database.py:91} INFO - Concurrent runs exceeded, retrying in 1 seconds...
[2024-07-16T07:53:27.897+0000] {etl_populate_database.py:91} INFO - Concurrent runs exceeded, retrying in 2 seconds...
[2024-07-16T07:53:30.022+0000] {etl_populate_database.py:91} INFO - Concurrent runs exceeded, retrying in 4 seconds...
[2024-07-16T07:53:34.136+0000] {etl_populate_database.py:91} INFO - Concurrent runs exceeded, retrying in 8 seconds...
[2024-07-16T07:53:42.264+0000] {etl_populate_database.py:91} INFO - Concurrent runs exceeded, retrying in 16 seconds...
[2024-07-16T07:53:58.264+0000] {taskinstance.py:441} INFO - ::group::Post task execution logs
[2024-07-16T07:53:58.265+0000] {taskinstance.py:2905} ERROR - Task failed with exception
Traceback (most recent call last):
  File "/home/airflow/.local/lib/python3.12/site-packages/airflow/models/taskinstance.py", line 465, in _execute_task
    result = _execute_callable(context=context, **execute_callable_kwargs)
             ^^^^^^^^^^^^^^^^^^^^^^^^^^^^^^^^^^^^^^^^^^^^^^^^^^^^^^^^^^^^^
  File "/home/airflow/.local/lib/python3.12/site-packages/airflow/models/taskinstance.py", line 432, in _execute_callable
    return execute_callable(context=context, **execute_callable_kwargs)
           ^^^^^^^^^^^^^^^^^^^^^^^^^^^^^^^^^^^^^^^^^^^^^^^^^^^^^^^^^^^^
  File "/home/airflow/.local/lib/python3.12/site-packages/airflow/models/baseoperator.py", line 401, in wrapper
    return func(self, *args, **kwargs)
           ^^^^^^^^^^^^^^^^^^^^^^^^^^^
  File "/home/airflow/.local/lib/python3.12/site-packages/airflow/operators/python.py", line 235, in execute
    return_value = self.execute_callable()
                   ^^^^^^^^^^^^^^^^^^^^^^^
  File "/home/airflow/.local/lib/python3.12/site-packages/airflow/operators/python.py", line 252, in execute_callable
    return self.python_callable(*self.op_args, **self.op_kwargs)
           ^^^^^^^^^^^^^^^^^^^^^^^^^^^^^^^^^^^^^^^^^^^^^^^^^^^^^
  File "/opt/airflow/dags/etl_populate_database.py", line 93, in start_glue_job
    raise Exception("Failed to start Glue job after multiple attempts due to ConcurrentRunsExceededException.")
Exception: Failed to start Glue job after multiple attempts due to ConcurrentRunsExceededException.
[2024-07-16T07:53:58.275+0000] {taskinstance.py:1206} INFO - Marking task as UP_FOR_RETRY. dag_id=glue_crawler_etl_pipeline, task_id=start_glue_job, run_id=manual__2024-07-16T07:49:57.063900+00:00, execution_date=20240716T074957, start_date=20240716T075326, end_date=20240716T075358
[2024-07-16T07:53:58.287+0000] {standard_task_runner.py:110} ERROR - Failed to execute job 299 for task start_glue_job (Failed to start Glue job after multiple attempts due to ConcurrentRunsExceededException.; 2943)
[2024-07-16T07:53:58.302+0000] {local_task_job_runner.py:240} INFO - Task exited with return code 1
[2024-07-16T07:53:58.322+0000] {taskinstance.py:3503} INFO - 0 downstream tasks scheduled from follow-on schedule check
[2024-07-16T07:53:58.325+0000] {local_task_job_runner.py:222} INFO - ::endgroup::
