[2024-07-12T03:57:28.431+0000] {local_task_job_runner.py:120} INFO - ::group::Pre task execution logs
[2024-07-12T03:57:28.446+0000] {taskinstance.py:2076} INFO - Dependencies all met for dep_context=non-requeueable deps ti=<TaskInstance: download_and_upload_to_s3.upload_to_s3 scheduled__2024-07-11T00:00:00+00:00 [queued]>
[2024-07-12T03:57:28.454+0000] {taskinstance.py:2076} INFO - Dependencies all met for dep_context=requeueable deps ti=<TaskInstance: download_and_upload_to_s3.upload_to_s3 scheduled__2024-07-11T00:00:00+00:00 [queued]>
[2024-07-12T03:57:28.455+0000] {taskinstance.py:2306} INFO - Starting attempt 1 of 2
[2024-07-12T03:57:28.467+0000] {taskinstance.py:2330} INFO - Executing <Task(PythonOperator): upload_to_s3> on 2024-07-11 00:00:00+00:00
[2024-07-12T03:57:28.472+0000] {warnings.py:112} WARNING - /home/***/.local/lib/python3.12/site-packages/***/task/task_runner/standard_task_runner.py:61: DeprecationWarning: This process (pid=602) is multi-threaded, use of fork() may lead to deadlocks in the child.
  pid = os.fork()

[2024-07-12T03:57:28.474+0000] {standard_task_runner.py:63} INFO - Started process 603 to run task
[2024-07-12T03:57:28.474+0000] {standard_task_runner.py:90} INFO - Running: ['***', 'tasks', 'run', 'download_and_upload_to_s3', 'upload_to_s3', 'scheduled__2024-07-11T00:00:00+00:00', '--job-id', '128', '--raw', '--subdir', 'DAGS_FOLDER/download_extract_dag.py', '--cfg-path', '/tmp/tmpy8loif5z']
[2024-07-12T03:57:28.475+0000] {standard_task_runner.py:91} INFO - Job 128: Subtask upload_to_s3
[2024-07-12T03:57:28.512+0000] {task_command.py:426} INFO - Running <TaskInstance: download_and_upload_to_s3.upload_to_s3 scheduled__2024-07-11T00:00:00+00:00 [running]> on host 4292072e8878
[2024-07-12T03:57:28.593+0000] {taskinstance.py:2648} INFO - Exporting env vars: AIRFLOW_CTX_DAG_OWNER='***' AIRFLOW_CTX_DAG_ID='download_and_upload_to_s3' AIRFLOW_CTX_TASK_ID='upload_to_s3' AIRFLOW_CTX_EXECUTION_DATE='2024-07-11T00:00:00+00:00' AIRFLOW_CTX_TRY_NUMBER='1' AIRFLOW_CTX_DAG_RUN_ID='scheduled__2024-07-11T00:00:00+00:00'
[2024-07-12T03:57:28.594+0000] {taskinstance.py:430} INFO - ::endgroup::
[2024-07-12T03:57:28.622+0000] {base.py:84} INFO - Using connection ID 's3-bucket-conn' for task execution.
[2024-07-12T03:57:28.622+0000] {connection_wrapper.py:384} INFO - AWS Connection (conn_id='s3-bucket-conn', conn_type='aws') credentials retrieved from login and password.
[2024-07-12T03:57:29.425+0000] {download_extract_dag.py:58} ERROR - Failed to upload /tmp/yourfile.zip to S3: Failed to upload /tmp/yourfile.zip to ipl-data-analysis-zipfile/yourfile.zip: An error occurred (InvalidAccessKeyId) when calling the PutObject operation: The AWS Access Key Id you provided does not exist in our records.
[2024-07-12T03:57:29.426+0000] {taskinstance.py:441} INFO - ::group::Post task execution logs
[2024-07-12T03:57:29.426+0000] {taskinstance.py:2905} ERROR - Task failed with exception
Traceback (most recent call last):
  File "/home/airflow/.local/lib/python3.12/site-packages/boto3/s3/transfer.py", line 371, in upload_file
    future.result()
  File "/home/airflow/.local/lib/python3.12/site-packages/s3transfer/futures.py", line 103, in result
    return self._coordinator.result()
           ^^^^^^^^^^^^^^^^^^^^^^^^^^
  File "/home/airflow/.local/lib/python3.12/site-packages/s3transfer/futures.py", line 266, in result
    raise self._exception
  File "/home/airflow/.local/lib/python3.12/site-packages/s3transfer/tasks.py", line 139, in __call__
    return self._execute_main(kwargs)
           ^^^^^^^^^^^^^^^^^^^^^^^^^^
  File "/home/airflow/.local/lib/python3.12/site-packages/s3transfer/tasks.py", line 162, in _execute_main
    return_value = self._main(**kwargs)
                   ^^^^^^^^^^^^^^^^^^^^
  File "/home/airflow/.local/lib/python3.12/site-packages/s3transfer/upload.py", line 764, in _main
    client.put_object(Bucket=bucket, Key=key, Body=body, **extra_args)
  File "/home/airflow/.local/lib/python3.12/site-packages/botocore/client.py", line 565, in _api_call
    return self._make_api_call(operation_name, kwargs)
           ^^^^^^^^^^^^^^^^^^^^^^^^^^^^^^^^^^^^^^^^^^^
  File "/home/airflow/.local/lib/python3.12/site-packages/botocore/client.py", line 1021, in _make_api_call
    raise error_class(parsed_response, operation_name)
botocore.exceptions.ClientError: An error occurred (InvalidAccessKeyId) when calling the PutObject operation: The AWS Access Key Id you provided does not exist in our records.

During handling of the above exception, another exception occurred:

Traceback (most recent call last):
  File "/home/airflow/.local/lib/python3.12/site-packages/airflow/models/taskinstance.py", line 465, in _execute_task
    result = _execute_callable(context=context, **execute_callable_kwargs)
             ^^^^^^^^^^^^^^^^^^^^^^^^^^^^^^^^^^^^^^^^^^^^^^^^^^^^^^^^^^^^^
  File "/home/airflow/.local/lib/python3.12/site-packages/airflow/models/taskinstance.py", line 432, in _execute_callable
    return execute_callable(context=context, **execute_callable_kwargs)
           ^^^^^^^^^^^^^^^^^^^^^^^^^^^^^^^^^^^^^^^^^^^^^^^^^^^^^^^^^^^^
  File "/home/airflow/.local/lib/python3.12/site-packages/airflow/models/baseoperator.py", line 401, in wrapper
    return func(self, *args, **kwargs)
           ^^^^^^^^^^^^^^^^^^^^^^^^^^^
  File "/home/airflow/.local/lib/python3.12/site-packages/airflow/operators/python.py", line 235, in execute
    return_value = self.execute_callable()
                   ^^^^^^^^^^^^^^^^^^^^^^^
  File "/home/airflow/.local/lib/python3.12/site-packages/airflow/operators/python.py", line 252, in execute_callable
    return self.python_callable(*self.op_args, **self.op_kwargs)
           ^^^^^^^^^^^^^^^^^^^^^^^^^^^^^^^^^^^^^^^^^^^^^^^^^^^^^
  File "/opt/airflow/dags/download_extract_dag.py", line 55, in upload_to_s3
    s3_hook.load_file(local_path, key=s3_key, bucket_name=bucket_name, replace=True)
  File "/home/airflow/.local/lib/python3.12/site-packages/airflow/providers/amazon/aws/hooks/s3.py", line 135, in wrapper
    return func(*bound_args.args, **bound_args.kwargs)
           ^^^^^^^^^^^^^^^^^^^^^^^^^^^^^^^^^^^^^^^^^^^
  File "/home/airflow/.local/lib/python3.12/site-packages/airflow/providers/amazon/aws/hooks/s3.py", line 89, in wrapper
    return func(*bound_args.args, **bound_args.kwargs)
           ^^^^^^^^^^^^^^^^^^^^^^^^^^^^^^^^^^^^^^^^^^^
  File "/home/airflow/.local/lib/python3.12/site-packages/airflow/providers/amazon/aws/hooks/s3.py", line 1098, in load_file
    client.upload_file(filename, bucket_name, key, ExtraArgs=extra_args, Config=self.transfer_config)
  File "/home/airflow/.local/lib/python3.12/site-packages/boto3/s3/inject.py", line 145, in upload_file
    return transfer.upload_file(
           ^^^^^^^^^^^^^^^^^^^^^
  File "/home/airflow/.local/lib/python3.12/site-packages/boto3/s3/transfer.py", line 377, in upload_file
    raise S3UploadFailedError(
boto3.exceptions.S3UploadFailedError: Failed to upload /tmp/yourfile.zip to ipl-data-analysis-zipfile/yourfile.zip: An error occurred (InvalidAccessKeyId) when calling the PutObject operation: The AWS Access Key Id you provided does not exist in our records.
[2024-07-12T03:57:29.436+0000] {taskinstance.py:1206} INFO - Marking task as UP_FOR_RETRY. dag_id=download_and_upload_to_s3, task_id=upload_to_s3, run_id=scheduled__2024-07-11T00:00:00+00:00, execution_date=20240711T000000, start_date=20240712T035728, end_date=20240712T035729
[2024-07-12T03:57:29.455+0000] {standard_task_runner.py:110} ERROR - Failed to execute job 128 for task upload_to_s3 (Failed to upload /tmp/yourfile.zip to ipl-data-analysis-zipfile/yourfile.zip: An error occurred (InvalidAccessKeyId) when calling the PutObject operation: The AWS Access Key Id you provided does not exist in our records.; 603)
[2024-07-12T03:57:29.490+0000] {local_task_job_runner.py:240} INFO - Task exited with return code 1
[2024-07-12T03:57:29.506+0000] {taskinstance.py:3503} INFO - 0 downstream tasks scheduled from follow-on schedule check
[2024-07-12T03:57:29.507+0000] {local_task_job_runner.py:222} INFO - ::endgroup::
