[2024-07-12T06:54:08.612+0000] {local_task_job_runner.py:120} INFO - ::group::Pre task execution logs
[2024-07-12T06:54:08.631+0000] {taskinstance.py:2076} INFO - Dependencies all met for dep_context=non-requeueable deps ti=<TaskInstance: upload_and_invoke_lambda.invoke_lambda_unzip manual__2024-07-12T06:54:01.152502+00:00 [queued]>
[2024-07-12T06:54:08.638+0000] {taskinstance.py:2076} INFO - Dependencies all met for dep_context=requeueable deps ti=<TaskInstance: upload_and_invoke_lambda.invoke_lambda_unzip manual__2024-07-12T06:54:01.152502+00:00 [queued]>
[2024-07-12T06:54:08.639+0000] {taskinstance.py:2306} INFO - Starting attempt 1 of 2
[2024-07-12T06:54:08.652+0000] {taskinstance.py:2330} INFO - Executing <Task(LambdaInvokeFunctionOperator): invoke_lambda_unzip> on 2024-07-12 06:54:01.152502+00:00
[2024-07-12T06:54:08.656+0000] {warnings.py:112} WARNING - /home/***/.local/lib/python3.12/site-packages/***/task/task_runner/standard_task_runner.py:61: DeprecationWarning: This process (pid=1636) is multi-threaded, use of fork() may lead to deadlocks in the child.
  pid = os.fork()

[2024-07-12T06:54:08.658+0000] {standard_task_runner.py:63} INFO - Started process 1637 to run task
[2024-07-12T06:54:08.658+0000] {standard_task_runner.py:90} INFO - Running: ['***', 'tasks', 'run', 'upload_and_invoke_lambda', 'invoke_lambda_unzip', 'manual__2024-07-12T06:54:01.152502+00:00', '--job-id', '204', '--raw', '--subdir', 'DAGS_FOLDER/stream_upload_to_s3.py', '--cfg-path', '/tmp/tmphp92wgg7']
[2024-07-12T06:54:08.659+0000] {standard_task_runner.py:91} INFO - Job 204: Subtask invoke_lambda_unzip
[2024-07-12T06:54:08.698+0000] {task_command.py:426} INFO - Running <TaskInstance: upload_and_invoke_lambda.invoke_lambda_unzip manual__2024-07-12T06:54:01.152502+00:00 [running]> on host 318b387ee83d
[2024-07-12T06:54:08.785+0000] {taskinstance.py:2648} INFO - Exporting env vars: AIRFLOW_CTX_DAG_OWNER='***' AIRFLOW_CTX_DAG_ID='upload_and_invoke_lambda' AIRFLOW_CTX_TASK_ID='invoke_lambda_unzip' AIRFLOW_CTX_EXECUTION_DATE='2024-07-12T06:54:01.152502+00:00' AIRFLOW_CTX_TRY_NUMBER='1' AIRFLOW_CTX_DAG_RUN_ID='manual__2024-07-12T06:54:01.152502+00:00'
[2024-07-12T06:54:08.786+0000] {taskinstance.py:430} INFO - ::endgroup::
[2024-07-12T06:54:08.797+0000] {lambda_function.py:217} INFO - Invoking AWS Lambda function: lambda_handler with payload: {"s3_key": "ipl_matches.zip"}
[2024-07-12T06:54:08.805+0000] {base.py:84} INFO - Using connection ID 's3-bucket-conn' for task execution.
[2024-07-12T06:54:08.805+0000] {connection_wrapper.py:384} INFO - AWS Connection (conn_id='s3-bucket-conn', conn_type='aws') credentials retrieved from login and password.
[2024-07-12T06:54:09.391+0000] {taskinstance.py:441} INFO - ::group::Post task execution logs
[2024-07-12T06:54:09.392+0000] {taskinstance.py:2905} ERROR - Task failed with exception
Traceback (most recent call last):
  File "/home/airflow/.local/lib/python3.12/site-packages/airflow/models/taskinstance.py", line 465, in _execute_task
    result = _execute_callable(context=context, **execute_callable_kwargs)
             ^^^^^^^^^^^^^^^^^^^^^^^^^^^^^^^^^^^^^^^^^^^^^^^^^^^^^^^^^^^^^
  File "/home/airflow/.local/lib/python3.12/site-packages/airflow/models/taskinstance.py", line 432, in _execute_callable
    return execute_callable(context=context, **execute_callable_kwargs)
           ^^^^^^^^^^^^^^^^^^^^^^^^^^^^^^^^^^^^^^^^^^^^^^^^^^^^^^^^^^^^
  File "/home/airflow/.local/lib/python3.12/site-packages/airflow/models/baseoperator.py", line 401, in wrapper
    return func(self, *args, **kwargs)
           ^^^^^^^^^^^^^^^^^^^^^^^^^^^
  File "/home/airflow/.local/lib/python3.12/site-packages/airflow/providers/amazon/aws/operators/lambda_function.py", line 218, in execute
    response = self.hook.invoke_lambda(
               ^^^^^^^^^^^^^^^^^^^^^^^^
  File "/home/airflow/.local/lib/python3.12/site-packages/airflow/providers/amazon/aws/hooks/lambda_function.py", line 83, in invoke_lambda
    return self.conn.invoke(**trim_none_values(invoke_args))
           ^^^^^^^^^^^^^^^^^^^^^^^^^^^^^^^^^^^^^^^^^^^^^^^^^
  File "/home/airflow/.local/lib/python3.12/site-packages/botocore/client.py", line 565, in _api_call
    return self._make_api_call(operation_name, kwargs)
           ^^^^^^^^^^^^^^^^^^^^^^^^^^^^^^^^^^^^^^^^^^^
  File "/home/airflow/.local/lib/python3.12/site-packages/botocore/client.py", line 1021, in _make_api_call
    raise error_class(parsed_response, operation_name)
botocore.errorfactory.ResourceNotFoundException: An error occurred (ResourceNotFoundException) when calling the Invoke operation: Function not found: arn:aws:lambda:us-east-2:590183781257:function:lambda_handler
[2024-07-12T06:54:09.400+0000] {taskinstance.py:1206} INFO - Marking task as UP_FOR_RETRY. dag_id=upload_and_invoke_lambda, task_id=invoke_lambda_unzip, run_id=manual__2024-07-12T06:54:01.152502+00:00, execution_date=20240712T065401, start_date=20240712T065408, end_date=20240712T065409
[2024-07-12T06:54:09.410+0000] {standard_task_runner.py:110} ERROR - Failed to execute job 204 for task invoke_lambda_unzip (An error occurred (ResourceNotFoundException) when calling the Invoke operation: Function not found: arn:aws:lambda:us-east-2:590183781257:function:lambda_handler; 1637)
[2024-07-12T06:54:09.433+0000] {local_task_job_runner.py:240} INFO - Task exited with return code 1
[2024-07-12T06:54:09.445+0000] {taskinstance.py:3503} INFO - 0 downstream tasks scheduled from follow-on schedule check
[2024-07-12T06:54:09.446+0000] {local_task_job_runner.py:222} INFO - ::endgroup::
